<?xml version="1.0"?>
<robot xmlns:xacro="http://www.ros.org/wiki/xacro" name="hera_description">

<xacro:include filename="$(find hera_description)/urdf/commons.urdf.xacro"/>

<!--base_link-->
  <xacro:macro name="create_base_link">
    <link name="base_link">
      <visual>
        <origin xyz="0 0 0" rpy="0 0 0" />
        <geometry>
          <mesh filename="package://hera_description/meshes/manip_meshes/base_link.STL"/>
        </geometry>
        <material name="">
          <color rgba="0.898039215686275 0.917647058823529 0.929411764705882 1" />
        </material>
      </visual>
      <collision>
        <origin xyz="0 0 0" rpy="0 0 0" />
        <geometry>
          <mesh filename="package://hera_description/meshes/manip_meshes/base_link.STL"/>
        </geometry>
      </collision>
      <xacro:inertial_base_link mass="0.225814419604843"/>
    </link>
  </xacro:macro>

<!--link_1-->
  <xacro:macro name="create_link_1">
    <link name="link_1">
      <visual>
        <origin xyz="0 0 0" rpy="0 0 0" />
        <geometry>
          <mesh filename="package://hera_description/meshes/manip_meshes/link_1.STL"/>
        </geometry>
        <material name="">
          <color rgba="0.996078431372549 0.996078431372549 1 1" />
        </material>
      </visual>
      <collision>
        <origin xyz="0 0 0" rpy="0 0 0" />
        <geometry>
          <mesh filename="package://hera_description/meshes/manip_meshes/link_1.STL"/>
        </geometry>
      </collision>
      <xacro:inertial_link_1 mass="0.0289102664622999"/>
    </link>

    <!--joint_1-->
    <joint name="joint_1" type="revolute">
      <origin xyz="0.0155 0 0.04515" rpy="0 0 0" />
      <parent link="base_link" />
      <child link="link_1" />
      <axis xyz="0 0 1" />
      <limit lower="-3.14" upper="3.14" effort="8" velocity="5" />
    </joint>
  </xacro:macro>

<!--link_2-->
  <xacro:macro name="create_link_2">
    <link name="link_2">
      <visual>
        <origin xyz="0 0 0" rpy="0 0 0" />
        <geometry>
          <mesh filename="package://hera_description/meshes/manip_meshes/link_2.STL"/>
        </geometry>
        <material name="">
          <color rgba="0.898039215686275 0.917647058823529 0.929411764705882 1" />
        </material>
      </visual>
      <collision>
        <origin xyz="0 0 0" rpy="0 0 0" />
        <geometry>
          <mesh filename="package://hera_description/meshes/manip_meshes/link_2_col.STL"/>
        </geometry>
      </collision>
      <xacro:inertial_link_1 mass="0.611796741662792"/>
    </link>

    <!--joint_2--> 
    <joint name="joint_2" type="revolute">
      <origin xyz="0.048 0 0.02285" rpy="3.1416 -1.1781 -3.1416" />
      <parent link="link_1" />
      <child link="link_2" />
      <axis xyz="0 1 0" />
      <limit lower="-1.0847" upper="3.14" effort="8" velocity="5" />
    </joint>
  </xacro:macro>

<!--link_3-->
  <xacro:macro name="create_link_3">
    <link name="link_3">
      <visual>
        <origin xyz="0 0 0" rpy="0 0 0" />
        <geometry>
          <mesh filename="package://hera_description/meshes/manip_meshes/link_3.STL"/>
        </geometry>
        <material name="">
          <color rgba="0.996078431372549 0.996078431372549 1 1" />
        </material>
      </visual>
      <collision>
        <origin xyz="0 0 0" rpy="0 0 0" />
        <geometry>
          <mesh filename="package://hera_description/meshes/manip_meshes/link_3_col.STL"/>
        </geometry>
      </collision>
      <xacro:inertial_link_1 mass="0.0289102660424069"/>
    </link>

    <!--joint_3-->  
    <joint name="joint_3" type="revolute">
      <origin xyz="0.1439 0 0" rpy="0 0 0" />
      <parent link="link_2" />
      <child link="link_3" />
      <axis xyz="1 0 0" />
      <limit lower="-3.14" upper="3.14" effort="8" velocity="5" />
    </joint>
  </xacro:macro>

<!--link_4-->
  <xacro:macro name="create_link_4">
    <link name="link_4">
      <visual>
        <origin xyz="0 0 0" rpy="0 0 0" />
        <geometry>
          <mesh filename="package://hera_description/meshes/manip_meshes/link_4.STL"/>
        </geometry>
        <material name="">
          <color rgba="0.898039215686275 0.917647058823529 0.929411764705882 1" />
        </material>
      </visual>
      <collision>
        <origin xyz="0 0 0" rpy="0 0 0" />
        <geometry>
          <mesh filename="package://hera_description/meshes/manip_meshes/link_4_col.STL"/>
        </geometry>
      </collision>
      <xacro:inertial_link_1 mass="0.611796742118779"/>
    </link>

    <!--joint_4-->
    <joint name="joint_4" type="revolute">
      <origin xyz="0.02285 0 -0.048" rpy="0 -0.3927 0" />
      <parent link="link_3" />
      <child link="link_4" />
      <axis xyz="0 -1 0" />
      <limit lower="-3.14" upper="1.0078" effort="8" velocity="5" />
    </joint>
  </xacro:macro>

<!-- link 5 -->
  <xacro:macro name="create_link_5">
    <link name="link_5">
      <visual>
        <origin xyz="0 0 0" rpy="0 0 0"/>
        <geometry>
          <mesh  filename="package://hera_description/meshes/manip_meshes/link_5.STL" />
        </geometry>
        <material name="">
          <color rgba="0.898039215686275 0.917647058823529 0.929411764705882 1"/>
        </material>
      </visual>
      <collision>
        <origin xyz="0 0 0" rpy="0 0 0"/>
        <geometry>
          <mesh filename="package://hera_description/meshes/manip_meshes/link_5_col.STL" />
        </geometry>
      </collision> 
      <xacro:inertial_link_5 mass="0.0368976416562371"/>
    </link>

    <!--joint_5--> 
    <joint name="joint_5" type="revolute">
      <origin xyz="0.1439 0 0" rpy="0 0 0" />
      <parent link="link_4" />
      <child link="link_5" />
      <axis xyz="1 0 0" />
      <limit lower="-3.14" upper="3.14" effort="8" velocity="5" />
    </joint>
  </xacro:macro>

<!-- link 6 -->
  <xacro:macro name="create_link_6">
    <link name="link_6">
      <visual>
        <origin xyz="0 0 0" rpy="0 0 0"/>
        <geometry>
          <mesh  filename="package://hera_description/meshes/manip_meshes/link_6.STL" />
        </geometry>
        <material name="">
          <color rgba="0.898039215686275 0.917647058823529 0.929411764705882 1"/>
        </material>
      </visual>
      <collision>
        <origin xyz="0 0 0" rpy="0 0 0"/>
        <geometry>
          <mesh filename="package://hera_description/meshes/manip_meshes/link_6_col.STL" />
        </geometry>
        </collision>
        <xacro:inertial_link_6 mass="0.482627734525522"/> 
    </link>

    <!--joint_6-->
    <joint name="joint_6" type="revolute">
      <origin xyz="0.03885 0 0" rpy="0 -0.3927 0" />
      <parent link="link_5" />
      <child link="link_6" />
      <axis xyz="0 -1 0" />
      <limit lower="-2.6232" upper="1.8262" effort="8" velocity="5" />
    </joint>
  </xacro:macro>

<!--link_7-->
  <xacro:macro name="create_link_7">
    <link name="link_7">
      <visual>
        <origin xyz="0 0 0" rpy="0 0 0" />
        <geometry>
          <mesh filename="package://hera_description/meshes/manip_meshes/link_7.STL"/>
        </geometry>
        <material name="">
          <color rgba="0.898039215686275 0.917647058823529 0.929411764705882 1" />
        </material>
      </visual>
      <collision>
        <origin xyz="0 0 0" rpy="0 0 0" />
        <geometry>
          <mesh filename="package://hera_description/meshes/manip_meshes/link_7_col.STL"/>
        </geometry>
      </collision>
      <xacro:inertial_link_7 mass="0.0392347304267543"/>
    </link>

    <!-- joint 7 -->
    <joint name="joint_7" type="revolute">
      <origin xyz="0.061 0.02125 0" rpy="0 0 0" />
      <parent link="link_6" />
      <child  link="link_7" />
      <axis xyz="0 0 1" />
      <limit lower="-0.6454" upper="1.5600" effort="8" velocity="5" />
    </joint>
  </xacro:macro>

<!--link_end7-->
  <xacro:macro name="create_link_end7">
    <link name="link_end7">
      <visual>
        <origin xyz="0 0 0" rpy="0 0 0" />
        <geometry>
          <mesh filename="package://hera_description/meshes/manip_meshes/link_end7.STL"/>
        </geometry>
        <material name="">
          <color rgba="0.898039215686275 0.917647058823529 0.929411764705882 1" />
        </material>
      </visual>
      <collision>
        <origin xyz="0 0 0" rpy="0 0 0" />
        <geometry>
          <mesh filename="package://hera_description/meshes/manip_meshes/link_end7.STL"/>
        </geometry>
      </collision>
      <xacro:inertial_link_end7 mass="0.0535201883186937"/>
    </link>

    <!--joint_end7-->
    <joint name="joint_end7" type="fixed">
      <origin xyz="0.066179 -0.02125 0" rpy="0 0 0" />
      <parent link="link_7" />
      <child link="link_end7" />
      <axis xyz="0 0 0" />
    </joint>
  </xacro:macro>

<!--link_8-->
  <xacro:macro name="create_link_8">
    <link name="link_8">
      <visual>
        <origin xyz="0 0 0" rpy="0 0 0" />
        <geometry>
          <mesh filename="package://hera_description/meshes/manip_meshes/link_8.STL" />
        </geometry>
        <material name="">
          <color rgba="0.898039215686275 0.917647058823529 0.929411764705882 1" />
        </material>
      </visual>
      <collision>
        <origin xyz="0 0 0" rpy="0 0 0" />
        <geometry>
          <mesh filename="package://hera_description/meshes/manip_meshes/link_8_col.STL" />
        </geometry>
      </collision>
      <xacro:inertial_link_8 mass="0.0392347308783591"/>
    </link>

    <!--joint_8--> 
    <joint name="joint_8" type="revolute">
      <origin xyz="0.061 -0.02125 0" rpy="0 0 0" />
      <parent link="link_6" />
      <child link="link_8" />
      <axis xyz="0 0 1" />
      <limit lower="-1.5600" upper="0.6454" effort="8" velocity="5" />
    </joint>
  </xacro:macro>

<!--link_end8-->
  <xacro:macro name="create_link_end8">
    <link name="link_end8">
      <visual>
        <origin xyz="0 0 0" rpy="0 0 0" />
        <geometry>
          <mesh filename="package://hera_description/meshes/manip_meshes/link_end8.STL" />
        </geometry>
        <material name="">
          <color rgba="0.898039215686275 0.917647058823529 0.929411764705882 1" />
        </material>
      </visual>
      <collision>
        <origin xyz="0 0 0" rpy="0 0 0" />
        <geometry>
          <mesh filename="package://hera_description/meshes/manip_meshes/link_end8.STL" />
        </geometry>
      </collision>
      <xacro:inertial_link_end8 mass="0.0535202013033793"/>
    </link>

    <!--joint_end8--> 
    <joint name="joint_end8" type="fixed">
      <origin xyz="0.0661786041848968 0.0212499999999973 0" rpy="0 0 0" />
      <parent link="link_8" />
      <child link="link_end8" />
      <axis xyz="0 0 0" />
    </joint>
  </xacro:macro>

  <xacro:macro name="manip">

    <!--base_link-->
    <xacro:create_base_link/>
    
    <!--link_1-->
    <xacro:create_link_1/>

    <!--link_2-->
    <xacro:create_link_2/>

    <!--link_3-->
    <xacro:create_link_3/>

    <!--link_4-->
    <xacro:create_link_4/>

    <!--link_5-->
    <xacro:create_link_5/>

    <!--link_6-->
    <xacro:create_link_6/>

    <!--link_7-->
    <xacro:create_link_7/>

    <!--link_end7-->
    <xacro:create_link_end7/>

    <!--link_8-->
    <xacro:create_link_8/>

    <!--link_end8-->
    <xacro:create_link_end8/>
  
  </xacro:macro>

</robot>