<?xml version="1.0" encoding="utf-8"?>

<robot
  name="manip_description">
  <link
    name="base_link">
    <inertial>
      <origin
        xyz="0.00030938336056912 -9.89895665437501E-13 0.0229511892881233"
        rpy="0 0 0" />
      <mass
        value="0.225814419604843" />
      <inertia
        ixx="5.65453718592828E-05"
        ixy="5.00162232371705E-16"
        ixz="-1.38639831470138E-06"
        iyy="0.000101241328443196"
        iyz="-3.18870100704921E-15"
        izz="8.47747908239031E-05" />
    </inertial>
    <visual>
      <origin
        xyz="0 0 0"
        rpy="0 0 0" />
      <geometry>
        <mesh
          filename="package://manip_description/meshes/base_link.STL" />
      </geometry>
      <material
        name="">
        <color
          rgba="0.898039215686275 0.917647058823529 0.929411764705882 1" />
      </material>
    </visual>
    <collision>
      <origin
        xyz="0 0 0"
        rpy="0 0 0" />
      <geometry>
        <mesh
          filename="package://manip_description/meshes/base_link_col.STL" />
      </geometry>
    </collision>
  </link>
  <link
    name="link_1">
    <inertial>
      <origin
        xyz="0.010403379929175 1.63335446591584E-08 0.0169657675518438"
        rpy="0 0 0" />
      <mass
        value="0.0289102664622999" />
      <inertia
        ixx="2.12284942933575E-05"
        ixy="2.48129475489142E-12"
        ixz="-1.76897405605609E-06"
        iyy="1.25993311294143E-05"
        iyz="3.2054762687646E-12"
        izz="2.59552674841784E-05" />
    </inertial>
    <visual>
      <origin
        xyz="0 0 0"
        rpy="0 0 0" />
      <geometry>
        <mesh
          filename="package://manip_description/meshes/link_1.STL" />
      </geometry>
      <material
        name="">
        <color
          rgba="0.996078431372549 0.996078431372549 1 1" />
      </material>
    </visual>
    <collision>
      <origin
        xyz="0 0 0"
        rpy="0 0 0" />
      <geometry>
        <mesh
          filename="package://manip_description/meshes/link_1_col.STL" />
      </geometry>
    </collision>
  </link>
  <joint
    name="joint_1"
    type="revolute">
    <origin
      xyz="0.0155 0 0.04515"
      rpy="0 0 0" />
    <parent
      link="base_link" />
    <child
      link="link_1" />
    <axis
      xyz="0 0 1" />
    <limit
      lower="-3.14"
      upper="3.14"
      effort="8"
      velocity="5" />
  </joint>
  <link
    name="link_2">
    <inertial>
      <origin
        xyz="0.0763705857165563 0.000254475982597022 0.00808212627192917"
        rpy="0 0 0" />
      <mass
        value="0.611796741662792" />
      <inertia
        ixx="0.000193142254231562"
        ixy="4.37085471306953E-07"
        ixz="-1.72353751616987E-05"
        iyy="0.000387146626280563"
        iyz="-1.13959846344025E-12"
        izz="0.000310532195206607" />
    </inertial>
    <visual>
      <origin
        xyz="0 0 0"
        rpy="0 0 0" />
      <geometry>
        <mesh
          filename="package://manip_description/meshes/link_2.STL" />
      </geometry>
      <material
        name="">
        <color
          rgba="0.898039215686275 0.917647058823529 0.929411764705882 1" />
      </material>
    </visual>
    <collision>
      <origin
        xyz="0 0 0"
        rpy="0 0 0" />
      <geometry>
        <mesh
          filename="package://manip_description/meshes/link_2_col.STL" />
      </geometry>
    </collision>
  </link>
  <joint
    name="joint_2"
    type="revolute">
    <origin
      xyz="0.048 0 0.02285"
      rpy="3.1416 -1.1781 -3.1416" />
    <parent
      link="link_1" />
    <child
      link="link_2" />
    <axis
      xyz="0 1 0" />
    <limit
      lower="-3.14"
      upper="3.14"
      effort="8"
      velocity="5" />
  </joint>
  <link
    name="link_3">
    <inertial>
      <origin
        xyz="0.0169657676446836 1.64819090528456E-08 -0.0104033800071373"
        rpy="0 0 0" />
      <mass
        value="0.0289102660424069" />
      <inertia
        ixx="2.5955267230398E-05"
        ixy="3.22328296007298E-12"
        ixz="1.76897404833607E-06"
        iyy="1.25993310604571E-05"
        iyz="-2.56726778703582E-12"
        izz="2.12284940766909E-05" />
    </inertial>
    <visual>
      <origin
        xyz="0 0 0"
        rpy="0 0 0" />
      <geometry>
        <mesh
          filename="package://manip_description/meshes/link_3.STL" />
      </geometry>
      <material
        name="">
        <color
          rgba="0.996078431372549 0.996078431372549 1 1" />
      </material>
    </visual>
    <collision>
      <origin
        xyz="0 0 0"
        rpy="0 0 0" />
      <geometry>
        <mesh
          filename="package://manip_description/meshes/link_3_col.STL" />
      </geometry>
    </collision>
  </link>
  <joint
    name="joint_3"
    type="revolute">
    <origin
      xyz="0.1439 0 0"
      rpy="0 0 0" />
    <parent
      link="link_2" />
    <child
      link="link_3" />
    <axis
      xyz="1 0 0" />
    <limit
      lower="-3.14"
      upper="3.14"
      effort="8"
      velocity="5" />
  </joint>
  <link
    name="link_4">
    <inertial>
      <origin
        xyz="0.0763705857419602 -0.00025447598295664 0.00808212650131321"
        rpy="0 0 0" />
      <mass
        value="0.611796742118779" />
      <inertia
        ixx="0.000193142254252889"
        ixy="-4.37085476272942E-07"
        ixz="-1.72353755052685E-05"
        iyy="0.000387146626356831"
        iyz="-1.13953084591342E-12"
        izz="0.000310532195285594" />
    </inertial>
    <visual>
      <origin
        xyz="0 0 0"
        rpy="0 0 0" />
      <geometry>
        <mesh
          filename="package://manip_description/meshes/link_4.STL" />
      </geometry>
      <material
        name="">
        <color
          rgba="0.898039215686275 0.917647058823529 0.929411764705882 1" />
      </material>
    </visual>
    <collision>
      <origin
        xyz="0 0 0"
        rpy="0 0 0" />
      <geometry>
        <mesh
          filename="package://manip_description/meshes/link_4_col.STL" />
      </geometry>
    </collision>
  </link>
  <joint
    name="joint_4"
    type="revolute">
    <origin
      xyz="0.02285 0 -0.048"
      rpy="0 -0.3927 0" />
    <parent
      link="link_3" />
    <child
      link="link_4" />
    <axis
      xyz="0 -1 0" />
    <limit
      lower="-3.14"
      upper="1.0078"
      effort="8"
      velocity="5" />
  </joint>
  <link
    name="link_5">
    <inertial>
      <origin
        xyz="0.0113429838803915 -3.46944695195361E-18 0"
        rpy="0 0 0" />
      <mass
        value="0.0368976416562371" />
      <inertia
        ixx="1.95927087211338E-05"
        ixy="7.26329421268603E-21"
        ixz="-2.5410988417629E-21"
        iyy="7.36984687037621E-06"
        iyz="8.60646127431738E-21"
        izz="2.02402124370273E-05" />
    </inertial>
    <visual>
      <origin
        xyz="0 0 0"
        rpy="0 0 0" />
      <geometry>
        <mesh
          filename="package://manip_description/meshes/link_5.STL" />
      </geometry>
      <material
        name="">
        <color
          rgba="0.898039215686275 0.917647058823529 0.929411764705882 1" />
      </material>
    </visual>
    <collision>
      <origin
        xyz="0 0 0"
        rpy="0 0 0" />
      <geometry>
        <mesh
          filename="package://manip_description/meshes/link_5_col.STL" />
      </geometry>
    </collision>
  </link>
  <joint
    name="joint_5"
    type="revolute">
    <origin
      xyz="0.1439 0 0"
      rpy="0 0 0" />
    <parent
      link="link_4" />
    <child
      link="link_5" />
    <axis
      xyz="1 0 0" />
    <limit
      lower="-3.14"
      upper="3.14"
      effort="8"
      velocity="5" />
  </joint>
  <link
    name="link_6">
    <inertial>
      <origin
        xyz="0.0386040770329412 -0.000322583154717528 0.000293719089379529"
        rpy="0 0 0" />
      <mass
        value="0.482627734525522" />
      <inertia
        ixx="0.000146386226397184"
        ixy="-4.37085473836754E-07"
        ixz="-1.5900787088928E-13"
        iyy="0.000125206462596505"
        iyz="-1.1391259066856E-12"
        izz="0.000181710835049005" />
    </inertial>
    <visual>
      <origin
        xyz="0 0 0"
        rpy="0 0 0" />
      <geometry>
        <mesh
          filename="package://manip_description/meshes/link_6.STL" />
      </geometry>
      <material
        name="">
        <color
          rgba="0.898039215686275 0.917647058823529 0.929411764705882 1" />
      </material>
    </visual>
    <collision>
      <origin
        xyz="0 0 0"
        rpy="0 0 0" />
      <geometry>
        <mesh
          filename="package://manip_description/meshes/link_6_col.STL" />
      </geometry>
    </collision>
  </link>
  <joint
    name="joint_6"
    type="revolute">
    <origin
      xyz="0.03885 0 0"
      rpy="0 -0.3927 0" />
    <parent
      link="link_5" />
    <child
      link="link_6" />
    <axis
      xyz="0 -1 0" />
    <limit
      lower="-2.3645"
      upper="1.5554"
      effort="8"
      velocity="5" />
  </joint>
  <link
    name="link_7">
    <inertial>
      <origin
        xyz="0.0224717905842797 0.025995105661012 -1.86855826922461E-08"
        rpy="0 0 0" />
      <mass
        value="0.0392347304267543" />
      <inertia
        ixx="1.12762059938717E-05"
        ixy="2.39164603983455E-07"
        ixz="-1.49908527899727E-12"
        iyy="1.06667583466197E-05"
        iyz="1.51683951155461E-12"
        izz="3.59815370093277E-06" />
    </inertial>
    <visual>
      <origin
        xyz="0 0 0"
        rpy="0 0 0" />
      <geometry>
        <mesh
          filename="package://manip_description/meshes/link_7.STL" />
      </geometry>
      <material
        name="">
        <color
          rgba="0.898039215686275 0.917647058823529 0.929411764705882 1" />
      </material>
    </visual>
    <collision>
      <origin
        xyz="0 0 0"
        rpy="0 0 0" />
      <geometry>
        <mesh
          filename="package://manip_description/meshes/link_7_col.STL" />
      </geometry>
    </collision>
  </link>
  <joint
    name="joint_7"
    type="revolute">
    <origin
      xyz="0.061 0.02125 0"
      rpy="0 0 0" />
    <parent
      link="link_6" />
    <child
      link="link_7" />
    <axis
      xyz="0 0 1" />
    <limit
      lower="-0.6454"
      upper="1.5600"
      effort="8"
      velocity="5" />
  </joint>
  <link
    name="link_end7">
    <inertial>
      <origin
        xyz="0.000799651866160656 0.0665118576297725 0.000157118505166365"
        rpy="0 0 0" />
      <mass
        value="0.0535201883186937" />
      <inertia
        ixx="2.29035041365173E-05"
        ixy="-1.8272694134383E-05"
        ixz="-1.47284953313777E-11"
        iyy="5.672487088308E-05"
        iyz="-6.47534317160686E-12"
        izz="5.94928785230653E-05" />
    </inertial>
    <visual>
      <origin
        xyz="0 0 0"
        rpy="0 0 0" />
      <geometry>
        <mesh
          filename="package://manip_description/meshes/link_end7.STL" />
      </geometry>
      <material
        name="">
        <color
          rgba="0.898039215686275 0.917647058823529 0.929411764705882 1" />
      </material>
    </visual>
    <collision>
      <origin
        xyz="0 0 0"
        rpy="0 0 0" />
      <geometry>
        <mesh
          filename="package://manip_description/meshes/link_end7.STL" />
      </geometry>
    </collision>
  </link>
  <joint
    name="joint_end7"
    type="fixed">
    <origin
      xyz="0.066179 -0.02125 0"
      rpy="0 0 0" />
    <parent
      link="link_7" />
    <child
      link="link_end7" />
    <axis
      xyz="0 0 0" />
  </joint>
  <link
    name="link_8">
    <inertial>
      <origin
        xyz="0.0224717906136957 -0.0259951056906864 1.87048285194003E-08"
        rpy="0 0 0" />
      <mass
        value="0.0392347308783591" />
      <inertia
        ixx="1.1276206158873E-05"
        ixy="-2.39164622388127E-07"
        ixz="1.41986509577831E-12"
        iyy="1.06667584951978E-05"
        iyz="1.37910726152201E-12"
        izz="3.5981537434786E-06" />
    </inertial>
    <visual>
      <origin
        xyz="0 0 0"
        rpy="0 0 0" />
      <geometry>
        <mesh
          filename="package://manip_description/meshes/link_8.STL" />
      </geometry>
      <material
        name="">
        <color
          rgba="0.898039215686275 0.917647058823529 0.929411764705882 1" />
      </material>
    </visual>
    <collision>
      <origin
        xyz="0 0 0"
        rpy="0 0 0" />
      <geometry>
        <mesh
          filename="package://manip_description/meshes/link_8_col.STL" />
      </geometry>
    </collision>
  </link>
  <joint
    name="joint_8"
    type="revolute">
    <origin
      xyz="0.061 -0.02125 0"
      rpy="0 0 0" />
    <parent
      link="link_6" />
    <child
      link="link_8" />
    <axis
      xyz="0 0 1" />
    <limit
      lower="-1.5600"
      upper="0.6454"
      effort="8"
      velocity="5" />
  </joint>
  <link
    name="link_end8">
    <inertial>
      <origin
        xyz="0.000799664295637492 -0.0665118622668557 0.00015710063142943"
        rpy="0 0 0" />
      <mass
        value="0.0535202013033793" />
      <inertia
        ixx="2.29035009049597E-05"
        ixy="1.82727115379582E-05"
        ixz="3.07510207373307E-11"
        iyy="5.67249052626609E-05"
        iyz="-1.11321771779834E-11"
        izz="5.94929088813273E-05" />
    </inertial>
    <visual>
      <origin
        xyz="0 0 0"
        rpy="0 0 0" />
      <geometry>
        <mesh
          filename="package://manip_description/meshes/link_end8.STL" />
      </geometry>
      <material
        name="">
        <color
          rgba="0.898039215686275 0.917647058823529 0.929411764705882 1" />
      </material>
    </visual>
    <collision>
      <origin
        xyz="0 0 0"
        rpy="0 0 0" />
      <geometry>
        <mesh
          filename="package://manip_description/meshes/link_end8.STL" />
      </geometry>
    </collision>
  </link>
  <joint
    name="joint_end8"
    type="fixed">
    <origin
      xyz="0.0661786041848968 0.0212499999999973 0"
      rpy="0 0 0" />
    <parent
      link="link_8" />
    <child
      link="link_end8" />
    <axis
      xyz="0 0 0" />
  </joint>
</robot>
